{"timestamp": "2025-06-01T10:59:26.003981", "level": "ERROR", "message": "Request failed", "module": "logger", "function": "__call__", "line": 112, "exception": {"type": "TypeError", "message": "'dict' object is not callable", "traceback": "Traceback (most recent call last):\n  File \"/usr/local/python/3.10.13/lib/python3.10/site-packages/starlette/middleware/base.py\", line 78, in call_next\n    message = await recv_stream.receive()\n  File \"/usr/local/python/3.10.13/lib/python3.10/site-packages/anyio/streams/memory.py\", line 98, in receive\n    return self.receive_nowait()\n  File \"/usr/local/python/3.10.13/lib/python3.10/site-packages/anyio/streams/memory.py\", line 91, in receive_nowait\n    raise EndOfStream\nanyio.EndOfStream\n\nDuring handling of the above exception, another exception occurred:\n\nTraceback (most recent call last):\n  File \"/project/sandbox/user-workspace/unisummarize/backend/utils/logger.py\", line 91, in __call__\n    response = await call_next(request)\n  File \"/usr/local/python/3.10.13/lib/python3.10/site-packages/starlette/middleware/base.py\", line 84, in call_next\n    raise app_exc\n  File \"/usr/local/python/3.10.13/lib/python3.10/site-packages/starlette/middleware/base.py\", line 70, in coro\n    await self.app(scope, receive_or_disconnect, send_no_error)\n  File \"/usr/local/python/3.10.13/lib/python3.10/site-packages/starlette/middleware/base.py\", line 109, in __call__\n    await response(scope, receive, send)\nTypeError: 'dict' object is not callable"}, "method": "GET", "url": "https://78sgvq-8000.csb.app/", "client_ip": "10.42.1.0", "headers": {"host": "78sgvq-8000.csb.app", "ssl-client-verify": "SUCCESS", "ssl-client-subject-dn": "CN=origin-pull.cloudflare.net,OU=Origin Pull,O=Cloudflare\\, Inc.,L=San Francisco,ST=California,C=US", "ssl-client-issuer-dn": "CN=origin-pull.cloudflare.net,ST=California,L=San Francisco,OU=Origin Pull,O=CloudFlare\\, Inc.,C=US", "x-request-id": "74fe6276780bc4a49cdad98f51b345d4", "x-real-ip": "10.42.1.0", "x-forwarded-for": "10.42.1.0", "sec-fetch-user": "?1", "x-forwarded-port": "443", "x-forwarded-proto": "https", "x-forwarded-scheme": "https", "x-scheme": "https", "x-original-forwarded-for": "2409:40f2:2165:189a:1c38:ade6:88c6:8839", "upgrade-insecure-requests": "1", "sec-fetch-site": "cross-site", "sec-fetch-mode": "navigate", "cf-ray": "948e339650ceb2b7-BLR", "cf-worker": "csb.app", "cf-ipcountry": "IN", "cf-visitor": "{\"scheme\":\"https\"}", "cf-ew-via": "15", "cdn-loop": "cloudflare; loops=1; subreqs=1", "accept-language": "en-IN,en-GB;q=0.9,en-US;q=0.8,en;q=0.7,hi;q=0.6,kn;q=0.5", "accept": "text/html,application/xhtml+xml,application/xml;q=0.9,image/avif,image/webp,image/apng,*/*;q=0.8,application/signed-exchange;v=b3;q=0.7", "referer": "https://agent.blackbox.ai/", "user-agent": "Mozilla/5.0 (Windows NT 10.0; Win64; x64) AppleWebKit/537.36 (KHTML, like Gecko) Chrome/136.0.0.0 Safari/537.36", "cf-connecting-ip": "2409:40f2:2165:189a:1c38:ade6:88c6:8839", "dnt": "1", "priority": "u=0, i", "sec-ch-ua": "\"Chromium\";v=\"136\", \"Google Chrome\";v=\"136\", \"Not.A/Brand\";v=\"99\"", "sec-ch-ua-mobile": "?0", "sec-ch-ua-platform": "\"Windows\"", "sec-fetch-dest": "document", "accept-encoding": "identity"}, "error": "'dict' object is not callable"}
{"timestamp": "2025-06-01T10:59:26.006315", "level": "ERROR", "message": "'dict' object is not callable", "module": "logger", "function": "log_error", "line": 125, "exception": {"type": "TypeError", "message": "'dict' object is not callable", "traceback": "Traceback (most recent call last):\n  File \"/usr/local/python/3.10.13/lib/python3.10/site-packages/starlette/middleware/base.py\", line 78, in call_next\n    message = await recv_stream.receive()\n  File \"/usr/local/python/3.10.13/lib/python3.10/site-packages/anyio/streams/memory.py\", line 98, in receive\n    return self.receive_nowait()\n  File \"/usr/local/python/3.10.13/lib/python3.10/site-packages/anyio/streams/memory.py\", line 91, in receive_nowait\n    raise EndOfStream\nanyio.EndOfStream\n\nDuring handling of the above exception, another exception occurred:\n\nTraceback (most recent call last):\n  File \"/usr/local/python/3.10.13/lib/python3.10/site-packages/starlette/middleware/errors.py\", line 162, in __call__\n    await self.app(scope, receive, _send)\n  File \"/usr/local/python/3.10.13/lib/python3.10/site-packages/starlette/middleware/base.py\", line 108, in __call__\n    response = await self.dispatch_func(request, call_next)\n  File \"/project/sandbox/user-workspace/unisummarize/backend/utils/logger.py\", line 91, in __call__\n    response = await call_next(request)\n  File \"/usr/local/python/3.10.13/lib/python3.10/site-packages/starlette/middleware/base.py\", line 84, in call_next\n    raise app_exc\n  File \"/usr/local/python/3.10.13/lib/python3.10/site-packages/starlette/middleware/base.py\", line 70, in coro\n    await self.app(scope, receive_or_disconnect, send_no_error)\n  File \"/usr/local/python/3.10.13/lib/python3.10/site-packages/starlette/middleware/base.py\", line 109, in __call__\n    await response(scope, receive, send)\nTypeError: 'dict' object is not callable"}, "context": {}}
{"timestamp": "2025-06-01T10:59:26.552459", "level": "ERROR", "message": "Request failed", "module": "logger", "function": "__call__", "line": 112, "exception": {"type": "TypeError", "message": "'dict' object is not callable", "traceback": "Traceback (most recent call last):\n  File \"/usr/local/python/3.10.13/lib/python3.10/site-packages/starlette/middleware/base.py\", line 78, in call_next\n    message = await recv_stream.receive()\n  File \"/usr/local/python/3.10.13/lib/python3.10/site-packages/anyio/streams/memory.py\", line 98, in receive\n    return self.receive_nowait()\n  File \"/usr/local/python/3.10.13/lib/python3.10/site-packages/anyio/streams/memory.py\", line 91, in receive_nowait\n    raise EndOfStream\nanyio.EndOfStream\n\nDuring handling of the above exception, another exception occurred:\n\nTraceback (most recent call last):\n  File \"/project/sandbox/user-workspace/unisummarize/backend/utils/logger.py\", line 91, in __call__\n    response = await call_next(request)\n  File \"/usr/local/python/3.10.13/lib/python3.10/site-packages/starlette/middleware/base.py\", line 84, in call_next\n    raise app_exc\n  File \"/usr/local/python/3.10.13/lib/python3.10/site-packages/starlette/middleware/base.py\", line 70, in coro\n    await self.app(scope, receive_or_disconnect, send_no_error)\n  File \"/usr/local/python/3.10.13/lib/python3.10/site-packages/starlette/middleware/base.py\", line 109, in __call__\n    await response(scope, receive, send)\nTypeError: 'dict' object is not callable"}, "method": "GET", "url": "https://78sgvq-8000.csb.app/favicon.ico", "client_ip": "10.42.1.0", "headers": {"host": "78sgvq-8000.csb.app", "ssl-client-verify": "SUCCESS", "ssl-client-subject-dn": "CN=origin-pull.cloudflare.net,OU=Origin Pull,O=Cloudflare\\, Inc.,L=San Francisco,ST=California,C=US", "ssl-client-issuer-dn": "CN=origin-pull.cloudflare.net,ST=California,L=San Francisco,OU=Origin Pull,O=CloudFlare\\, Inc.,C=US", "x-request-id": "b249b5238039ae9c9be11dc9fb136551", "x-real-ip": "10.42.1.0", "x-forwarded-for": "10.42.1.0", "dnt": "1", "x-forwarded-port": "443", "x-forwarded-proto": "https", "x-forwarded-scheme": "https", "x-scheme": "https", "x-original-forwarded-for": "2409:40f2:2165:189a:1c38:ade6:88c6:8839", "cf-ray": "948e339a01b7b2b7-BOS", "sec-ch-ua": "\"Chromium\";v=\"136\", \"Google Chrome\";v=\"136\", \"Not.A/Brand\";v=\"99\"", "priority": "u=1, i", "sec-ch-ua-mobile": "?0", "accept-encoding": "gzip", "sec-ch-ua-platform": "\"Windows\"", "cf-visitor": "{\"scheme\":\"https\"}", "cf-ipcountry": "IN", "cf-worker": "csb.app", "cf-connecting-ip": "2409:40f2:2165:189a:1c38:ade6:88c6:8839", "sec-fetch-site": "same-origin", "sec-fetch-mode": "no-cors", "sec-fetch-dest": "image", "cf-ew-via": "15", "cdn-loop": "cloudflare; loops=1; subreqs=1", "accept-language": "en-IN,en-GB;q=0.9,en-US;q=0.8,en;q=0.7,hi;q=0.6,kn;q=0.5", "accept": "image/avif,image/webp,image/apng,image/svg+xml,image/*,*/*;q=0.8", "referer": "https://78sgvq-8000.csb.app/", "user-agent": "Mozilla/5.0 (Windows NT 10.0; Win64; x64) AppleWebKit/537.36 (KHTML, like Gecko) Chrome/136.0.0.0 Safari/537.36"}, "error": "'dict' object is not callable"}
{"timestamp": "2025-06-01T10:59:26.553730", "level": "ERROR", "message": "'dict' object is not callable", "module": "logger", "function": "log_error", "line": 125, "exception": {"type": "TypeError", "message": "'dict' object is not callable", "traceback": "Traceback (most recent call last):\n  File \"/usr/local/python/3.10.13/lib/python3.10/site-packages/starlette/middleware/base.py\", line 78, in call_next\n    message = await recv_stream.receive()\n  File \"/usr/local/python/3.10.13/lib/python3.10/site-packages/anyio/streams/memory.py\", line 98, in receive\n    return self.receive_nowait()\n  File \"/usr/local/python/3.10.13/lib/python3.10/site-packages/anyio/streams/memory.py\", line 91, in receive_nowait\n    raise EndOfStream\nanyio.EndOfStream\n\nDuring handling of the above exception, another exception occurred:\n\nTraceback (most recent call last):\n  File \"/usr/local/python/3.10.13/lib/python3.10/site-packages/starlette/middleware/errors.py\", line 162, in __call__\n    await self.app(scope, receive, _send)\n  File \"/usr/local/python/3.10.13/lib/python3.10/site-packages/starlette/middleware/base.py\", line 108, in __call__\n    response = await self.dispatch_func(request, call_next)\n  File \"/project/sandbox/user-workspace/unisummarize/backend/utils/logger.py\", line 91, in __call__\n    response = await call_next(request)\n  File \"/usr/local/python/3.10.13/lib/python3.10/site-packages/starlette/middleware/base.py\", line 84, in call_next\n    raise app_exc\n  File \"/usr/local/python/3.10.13/lib/python3.10/site-packages/starlette/middleware/base.py\", line 70, in coro\n    await self.app(scope, receive_or_disconnect, send_no_error)\n  File \"/usr/local/python/3.10.13/lib/python3.10/site-packages/starlette/middleware/base.py\", line 109, in __call__\n    await response(scope, receive, send)\nTypeError: 'dict' object is not callable"}, "context": {}}
{"timestamp": "2025-06-01T11:01:20.342011", "level": "ERROR", "message": "Request failed", "module": "logger", "function": "__call__", "line": 112, "exception": {"type": "TypeError", "message": "'dict' object is not callable", "traceback": "Traceback (most recent call last):\n  File \"/usr/local/python/3.10.13/lib/python3.10/site-packages/starlette/middleware/base.py\", line 78, in call_next\n    message = await recv_stream.receive()\n  File \"/usr/local/python/3.10.13/lib/python3.10/site-packages/anyio/streams/memory.py\", line 98, in receive\n    return self.receive_nowait()\n  File \"/usr/local/python/3.10.13/lib/python3.10/site-packages/anyio/streams/memory.py\", line 91, in receive_nowait\n    raise EndOfStream\nanyio.EndOfStream\n\nDuring handling of the above exception, another exception occurred:\n\nTraceback (most recent call last):\n  File \"/project/sandbox/user-workspace/unisummarize/backend/utils/logger.py\", line 91, in __call__\n    response = await call_next(request)\n  File \"/usr/local/python/3.10.13/lib/python3.10/site-packages/starlette/middleware/base.py\", line 84, in call_next\n    raise app_exc\n  File \"/usr/local/python/3.10.13/lib/python3.10/site-packages/starlette/middleware/base.py\", line 70, in coro\n    await self.app(scope, receive_or_disconnect, send_no_error)\n  File \"/usr/local/python/3.10.13/lib/python3.10/site-packages/starlette/middleware/base.py\", line 109, in __call__\n    await response(scope, receive, send)\nTypeError: 'dict' object is not callable"}, "method": "GET", "url": "https://78sgvq-8000.csb.app/", "client_ip": "10.42.1.0", "headers": {"host": "78sgvq-8000.csb.app", "ssl-client-verify": "SUCCESS", "ssl-client-subject-dn": "CN=origin-pull.cloudflare.net,OU=Origin Pull,O=Cloudflare\\, Inc.,L=San Francisco,ST=California,C=US", "ssl-client-issuer-dn": "CN=origin-pull.cloudflare.net,ST=California,L=San Francisco,OU=Origin Pull,O=CloudFlare\\, Inc.,C=US", "x-request-id": "6bbaacb4092926ff6043eabd1efe8b3a", "x-real-ip": "10.42.1.0", "x-forwarded-for": "10.42.1.0", "sec-ch-ua": "\"Chromium\";v=\"136\", \"Google Chrome\";v=\"136\", \"Not.A/Brand\";v=\"99\"", "x-forwarded-port": "443", "x-forwarded-proto": "https", "x-forwarded-scheme": "https", "x-scheme": "https", "x-original-forwarded-for": "2409:40f2:2165:189a:1c38:ade6:88c6:8839", "cf-ray": "948e366134313d29-BOS", "sec-ch-ua-platform": "\"Windows\"", "sec-ch-ua-mobile": "?0", "sec-fetch-dest": "document", "dnt": "1", "sec-fetch-mode": "navigate", "cf-visitor": "{\"scheme\":\"https\"}", "cf-ipcountry": "IN", "cf-worker": "csb.app", "priority": "u=0, i", "upgrade-insecure-requests": "1", "sec-fetch-user": "?1", "sec-fetch-site": "cross-site", "cf-ew-via": "15", "cdn-loop": "cloudflare; loops=1; subreqs=1", "accept-language": "en-IN,en-GB;q=0.9,en-US;q=0.8,en;q=0.7,hi;q=0.6,kn;q=0.5", "accept": "text/html,application/xhtml+xml,application/xml;q=0.9,image/avif,image/webp,image/apng,*/*;q=0.8,application/signed-exchange;v=b3;q=0.7", "referer": "https://agent.blackbox.ai/", "user-agent": "Mozilla/5.0 (Windows NT 10.0; Win64; x64) AppleWebKit/537.36 (KHTML, like Gecko) Chrome/136.0.0.0 Safari/537.36", "cf-connecting-ip": "2409:40f2:2165:189a:1c38:ade6:88c6:8839", "accept-encoding": "identity"}, "error": "'dict' object is not callable"}
{"timestamp": "2025-06-01T11:01:20.343260", "level": "ERROR", "message": "'dict' object is not callable", "module": "logger", "function": "log_error", "line": 125, "exception": {"type": "TypeError", "message": "'dict' object is not callable", "traceback": "Traceback (most recent call last):\n  File \"/usr/local/python/3.10.13/lib/python3.10/site-packages/starlette/middleware/base.py\", line 78, in call_next\n    message = await recv_stream.receive()\n  File \"/usr/local/python/3.10.13/lib/python3.10/site-packages/anyio/streams/memory.py\", line 98, in receive\n    return self.receive_nowait()\n  File \"/usr/local/python/3.10.13/lib/python3.10/site-packages/anyio/streams/memory.py\", line 91, in receive_nowait\n    raise EndOfStream\nanyio.EndOfStream\n\nDuring handling of the above exception, another exception occurred:\n\nTraceback (most recent call last):\n  File \"/usr/local/python/3.10.13/lib/python3.10/site-packages/starlette/middleware/errors.py\", line 162, in __call__\n    await self.app(scope, receive, _send)\n  File \"/usr/local/python/3.10.13/lib/python3.10/site-packages/starlette/middleware/base.py\", line 108, in __call__\n    response = await self.dispatch_func(request, call_next)\n  File \"/project/sandbox/user-workspace/unisummarize/backend/utils/logger.py\", line 91, in __call__\n    response = await call_next(request)\n  File \"/usr/local/python/3.10.13/lib/python3.10/site-packages/starlette/middleware/base.py\", line 84, in call_next\n    raise app_exc\n  File \"/usr/local/python/3.10.13/lib/python3.10/site-packages/starlette/middleware/base.py\", line 70, in coro\n    await self.app(scope, receive_or_disconnect, send_no_error)\n  File \"/usr/local/python/3.10.13/lib/python3.10/site-packages/starlette/middleware/base.py\", line 109, in __call__\n    await response(scope, receive, send)\nTypeError: 'dict' object is not callable"}, "context": {}}
{"timestamp": "2025-06-01T11:01:20.894057", "level": "ERROR", "message": "Request failed", "module": "logger", "function": "__call__", "line": 112, "exception": {"type": "TypeError", "message": "'dict' object is not callable", "traceback": "Traceback (most recent call last):\n  File \"/usr/local/python/3.10.13/lib/python3.10/site-packages/starlette/middleware/base.py\", line 78, in call_next\n    message = await recv_stream.receive()\n  File \"/usr/local/python/3.10.13/lib/python3.10/site-packages/anyio/streams/memory.py\", line 98, in receive\n    return self.receive_nowait()\n  File \"/usr/local/python/3.10.13/lib/python3.10/site-packages/anyio/streams/memory.py\", line 91, in receive_nowait\n    raise EndOfStream\nanyio.EndOfStream\n\nDuring handling of the above exception, another exception occurred:\n\nTraceback (most recent call last):\n  File \"/project/sandbox/user-workspace/unisummarize/backend/utils/logger.py\", line 91, in __call__\n    response = await call_next(request)\n  File \"/usr/local/python/3.10.13/lib/python3.10/site-packages/starlette/middleware/base.py\", line 84, in call_next\n    raise app_exc\n  File \"/usr/local/python/3.10.13/lib/python3.10/site-packages/starlette/middleware/base.py\", line 70, in coro\n    await self.app(scope, receive_or_disconnect, send_no_error)\n  File \"/usr/local/python/3.10.13/lib/python3.10/site-packages/starlette/middleware/base.py\", line 109, in __call__\n    await response(scope, receive, send)\nTypeError: 'dict' object is not callable"}, "method": "GET", "url": "https://78sgvq-8000.csb.app/favicon.ico", "client_ip": "10.42.0.0", "headers": {"host": "78sgvq-8000.csb.app", "ssl-client-verify": "SUCCESS", "ssl-client-subject-dn": "CN=origin-pull.cloudflare.net,OU=Origin Pull,O=Cloudflare\\, Inc.,L=San Francisco,ST=California,C=US", "ssl-client-issuer-dn": "CN=origin-pull.cloudflare.net,ST=California,L=San Francisco,OU=Origin Pull,O=CloudFlare\\, Inc.,C=US", "x-request-id": "957d737c289653526c42889205c3644f", "x-real-ip": "10.42.0.0", "x-forwarded-for": "10.42.0.0", "dnt": "1", "x-forwarded-port": "443", "x-forwarded-proto": "https", "x-forwarded-scheme": "https", "x-scheme": "https", "x-original-forwarded-for": "2409:40f2:2165:189a:1c38:ade6:88c6:8839", "cf-ray": "948e3664b6453d29-BOS", "sec-ch-ua": "\"Chromium\";v=\"136\", \"Google Chrome\";v=\"136\", \"Not.A/Brand\";v=\"99\"", "priority": "u=1, i", "sec-ch-ua-mobile": "?0", "accept-encoding": "gzip", "sec-ch-ua-platform": "\"Windows\"", "cf-visitor": "{\"scheme\":\"https\"}", "cf-ipcountry": "IN", "cf-worker": "csb.app", "cf-connecting-ip": "2409:40f2:2165:189a:1c38:ade6:88c6:8839", "sec-fetch-site": "same-origin", "sec-fetch-mode": "no-cors", "sec-fetch-dest": "image", "cf-ew-via": "15", "cdn-loop": "cloudflare; loops=1; subreqs=1", "accept-language": "en-IN,en-GB;q=0.9,en-US;q=0.8,en;q=0.7,hi;q=0.6,kn;q=0.5", "accept": "image/avif,image/webp,image/apng,image/svg+xml,image/*,*/*;q=0.8", "referer": "https://78sgvq-8000.csb.app/", "user-agent": "Mozilla/5.0 (Windows NT 10.0; Win64; x64) AppleWebKit/537.36 (KHTML, like Gecko) Chrome/136.0.0.0 Safari/537.36"}, "error": "'dict' object is not callable"}
{"timestamp": "2025-06-01T11:01:20.895161", "level": "ERROR", "message": "'dict' object is not callable", "module": "logger", "function": "log_error", "line": 125, "exception": {"type": "TypeError", "message": "'dict' object is not callable", "traceback": "Traceback (most recent call last):\n  File \"/usr/local/python/3.10.13/lib/python3.10/site-packages/starlette/middleware/base.py\", line 78, in call_next\n    message = await recv_stream.receive()\n  File \"/usr/local/python/3.10.13/lib/python3.10/site-packages/anyio/streams/memory.py\", line 98, in receive\n    return self.receive_nowait()\n  File \"/usr/local/python/3.10.13/lib/python3.10/site-packages/anyio/streams/memory.py\", line 91, in receive_nowait\n    raise EndOfStream\nanyio.EndOfStream\n\nDuring handling of the above exception, another exception occurred:\n\nTraceback (most recent call last):\n  File \"/usr/local/python/3.10.13/lib/python3.10/site-packages/starlette/middleware/errors.py\", line 162, in __call__\n    await self.app(scope, receive, _send)\n  File \"/usr/local/python/3.10.13/lib/python3.10/site-packages/starlette/middleware/base.py\", line 108, in __call__\n    response = await self.dispatch_func(request, call_next)\n  File \"/project/sandbox/user-workspace/unisummarize/backend/utils/logger.py\", line 91, in __call__\n    response = await call_next(request)\n  File \"/usr/local/python/3.10.13/lib/python3.10/site-packages/starlette/middleware/base.py\", line 84, in call_next\n    raise app_exc\n  File \"/usr/local/python/3.10.13/lib/python3.10/site-packages/starlette/middleware/base.py\", line 70, in coro\n    await self.app(scope, receive_or_disconnect, send_no_error)\n  File \"/usr/local/python/3.10.13/lib/python3.10/site-packages/starlette/middleware/base.py\", line 109, in __call__\n    await response(scope, receive, send)\nTypeError: 'dict' object is not callable"}, "context": {}}
{"timestamp": "2025-06-01T11:01:27.038385", "level": "ERROR", "message": "Request failed", "module": "logger", "function": "__call__", "line": 112, "exception": {"type": "TypeError", "message": "'dict' object is not callable", "traceback": "Traceback (most recent call last):\n  File \"/usr/local/python/3.10.13/lib/python3.10/site-packages/starlette/middleware/base.py\", line 78, in call_next\n    message = await recv_stream.receive()\n  File \"/usr/local/python/3.10.13/lib/python3.10/site-packages/anyio/streams/memory.py\", line 98, in receive\n    return self.receive_nowait()\n  File \"/usr/local/python/3.10.13/lib/python3.10/site-packages/anyio/streams/memory.py\", line 91, in receive_nowait\n    raise EndOfStream\nanyio.EndOfStream\n\nDuring handling of the above exception, another exception occurred:\n\nTraceback (most recent call last):\n  File \"/project/sandbox/user-workspace/unisummarize/backend/utils/logger.py\", line 91, in __call__\n    response = await call_next(request)\n  File \"/usr/local/python/3.10.13/lib/python3.10/site-packages/starlette/middleware/base.py\", line 84, in call_next\n    raise app_exc\n  File \"/usr/local/python/3.10.13/lib/python3.10/site-packages/starlette/middleware/base.py\", line 70, in coro\n    await self.app(scope, receive_or_disconnect, send_no_error)\n  File \"/usr/local/python/3.10.13/lib/python3.10/site-packages/starlette/middleware/base.py\", line 109, in __call__\n    await response(scope, receive, send)\nTypeError: 'dict' object is not callable"}, "method": "GET", "url": "https://78sgvq-8000.csb.app/", "client_ip": "10.42.2.0", "headers": {"host": "78sgvq-8000.csb.app", "ssl-client-verify": "SUCCESS", "ssl-client-subject-dn": "CN=origin-pull.cloudflare.net,OU=Origin Pull,O=Cloudflare\\, Inc.,L=San Francisco,ST=California,C=US", "ssl-client-issuer-dn": "CN=origin-pull.cloudflare.net,ST=California,L=San Francisco,OU=Origin Pull,O=CloudFlare\\, Inc.,C=US", "x-request-id": "21880e65d92f93f4e4c0b0c2cce72bf7", "x-real-ip": "10.42.2.0", "x-forwarded-for": "10.42.2.0", "dnt": "1", "x-forwarded-port": "443", "x-forwarded-proto": "https", "x-forwarded-scheme": "https", "x-scheme": "https", "x-original-forwarded-for": "2409:40f2:2165:189a:1c38:ade6:88c6:8839", "cf-ray": "948e368b26673d29-BOS", "sec-ch-ua": "\"Chromium\";v=\"136\", \"Google Chrome\";v=\"136\", \"Not.A/Brand\";v=\"99\"", "priority": "u=1, i", "sec-ch-ua-mobile": "?0", "accept-encoding": "gzip", "sec-ch-ua-platform": "\"Windows\"", "cf-visitor": "{\"scheme\":\"https\"}", "cf-ipcountry": "IN", "cf-worker": "csb.app", "cf-connecting-ip": "2409:40f2:2165:189a:1c38:ade6:88c6:8839", "sec-fetch-site": "same-origin", "sec-fetch-mode": "no-cors", "sec-fetch-dest": "empty", "cf-ew-via": "15", "cdn-loop": "cloudflare; loops=1; subreqs=1", "accept-language": "en-IN,en-GB;q=0.9,en-US;q=0.8,en;q=0.7,hi;q=0.6,kn;q=0.5", "accept": "*/*", "referer": "https://agent.blackbox.ai/", "user-agent": "Mozilla/5.0 (Windows NT 10.0; Win64; x64) AppleWebKit/537.36 (KHTML, like Gecko) Chrome/136.0.0.0 Safari/537.36"}, "error": "'dict' object is not callable"}
{"timestamp": "2025-06-01T11:01:27.039353", "level": "ERROR", "message": "'dict' object is not callable", "module": "logger", "function": "log_error", "line": 125, "exception": {"type": "TypeError", "message": "'dict' object is not callable", "traceback": "Traceback (most recent call last):\n  File \"/usr/local/python/3.10.13/lib/python3.10/site-packages/starlette/middleware/base.py\", line 78, in call_next\n    message = await recv_stream.receive()\n  File \"/usr/local/python/3.10.13/lib/python3.10/site-packages/anyio/streams/memory.py\", line 98, in receive\n    return self.receive_nowait()\n  File \"/usr/local/python/3.10.13/lib/python3.10/site-packages/anyio/streams/memory.py\", line 91, in receive_nowait\n    raise EndOfStream\nanyio.EndOfStream\n\nDuring handling of the above exception, another exception occurred:\n\nTraceback (most recent call last):\n  File \"/usr/local/python/3.10.13/lib/python3.10/site-packages/starlette/middleware/errors.py\", line 162, in __call__\n    await self.app(scope, receive, _send)\n  File \"/usr/local/python/3.10.13/lib/python3.10/site-packages/starlette/middleware/base.py\", line 108, in __call__\n    response = await self.dispatch_func(request, call_next)\n  File \"/project/sandbox/user-workspace/unisummarize/backend/utils/logger.py\", line 91, in __call__\n    response = await call_next(request)\n  File \"/usr/local/python/3.10.13/lib/python3.10/site-packages/starlette/middleware/base.py\", line 84, in call_next\n    raise app_exc\n  File \"/usr/local/python/3.10.13/lib/python3.10/site-packages/starlette/middleware/base.py\", line 70, in coro\n    await self.app(scope, receive_or_disconnect, send_no_error)\n  File \"/usr/local/python/3.10.13/lib/python3.10/site-packages/starlette/middleware/base.py\", line 109, in __call__\n    await response(scope, receive, send)\nTypeError: 'dict' object is not callable"}, "context": {}}
